Workbook
Name UPDATE: 'Data Sheet'!$E$1

Sheet Assumptions
C1: Bharat Electronics Ltd
B5: Company Name | C5: BHARAT ELECTRONICS LTD
B6: ISIN Code | C6: INE263A01024
B7: Sector Name | C7: AEROSPACE & DEFENCE
B8: Industry | C8: ELECTRONICS & DEFENCE
B9: Exchange Name | C9: BSE: 532959, NSE: BEL
B10: Website | C10: https://bel-india.in | AN10: Particulars | AO10: FY2026 | AP10: FY2027 | AQ10: FY2028 | AR10: FY2029 | AS10: FY2030 | AT10: FY2031 | AU10: FY2032 | AV10: FY2033 | AW10: FY2034 | AX10: FY2035
B11: Company Description | C11: Bharat Electronics Ltd (BEL) is a government-owned aerospace and defence electronics company under the Ministry of Defence, Government of India. The company designs, develops, manufactures, and supplies advanced electronic systems and equipment for defence and civilian applications. Its product portfolio includes radar systems, sonar systems, electronic warfare systems, communication systems, weapon systems, avionics, night vision devices, electro-optics, and homeland security solutions. BEL also provides software-defined radios, satellite communication systems, electronic voting machines, and smart city solutions. It primarily serves the Indian Army, Indian Navy, Indian Air Force, Indian Coast Guard, DRDO, ISRO, and Paramilitary forces, along with select export markets. BEL is headquartered in Bengaluru, Karnataka, India. | AN11: Base Case | AO11: 0.15 | AP11: 0.14 | AQ11: 0.135 | AR11: 0.13 | AS11: 0.125 | AT11: 0.12 | AU11: 0.115 | AV11: 0.11 | AW11: 0.105 | AX11: 0.1
B12: Price (INR) | C12: 272 | AN12: Bull Case | AO12: 0.18 | AP12: 0.17 | AQ12: 0.17 | AR12: 0.16 | AS12: 0.15 | AT12: 0.145 | AU12: 0.14 | AV12: 0.135 | AW12: 0.13 | AX12: 0.125
AN13: Bear Case | AO13: 0.1 | AP13: 0.095 | AQ13: 0.09 | AR13: 0.085 | AS13: 0.08 | AT13: 0.075 | AU13: 0.07 | AV13: 0.065 | AW13: 0.06 | AX13: 0.055
B14: Assumption Type | C14: Case No.
B15: Bull Case | C15: 2
D18: Particulars | E18: FY2026 | F18: FY2027 | G18: FY2028 | H18: FY2029 | I18: FY2030 | J18: FY2031 | K18: FY2032 | L18: FY2033 | M18: FY2034 | N18: FY2035
B19: Transaction Date | C19: 45516 | D19: Base Case | E19: 0.15 | F19: 0.14 | G19: 0.135 | H19: 0.13 | I19: 0.125 | J19: 0.12 | K19: 0.115 | L19: 0.11 | M19: 0.105 | N19: 0.1
B20: Fiscal Year End | C20: 45747 | D20: Bull Case | E20: 0.18 | F20: 0.17 | G20: 0.17 | H20: 0.16 | I20: 0.15 | J20: 0.145 | K20: 0.14 | L20: 0.135 | M20: 0.13 | N20: 0.125
B21: Risk Free Rate | C21: 0.07192 | D21: Bear Case | E21: 0.1 | F21: 0.095 | G21: 0.09 | H21: 0.085 | I21: 0.08 | J21: 0.075 | K21: 0.07 | L21: 0.065 | M21: 0.06 | N21: 0.055
B22: Tax Rate | C22: 0.255
B23: EV/EBITDA Multiple | C23: ='[1]comps valuation'!R11 -> 5.4069884
B24: Perpetual Growth Rate | C24: 0.06
B25: Discount Rate | C25: =WACC!G36 -> 0.255
B26: Shares Outstanding | C26: ='[1]comps valuation'!G11 -> 2029.4
B27: Current Price | C27: 272
B28: Sheet Name | C28: Row/Cell Referencing | D28: Comments
B29: Assumptions | C29: Case Selection Cell | D29: User selection dropdown provided with three scenarios — Base, Bull, Bear. Model assumptions and projections will dynamically update based on selected case.
B30: Assumptions | C30: Revenue Growth Input Cells | D30: User input cells provided for revenue growth rates per year. Historical 5-year revenue CAGR of ~13.8% (FY2021–FY2025) has been used as the base driver for forecasting future revenues.
B31: Assumptions | C31: Risk Free Rate Cell | D31: 10-year India Government benchmark bond yield linked across the model wherever required for WACC and DCF calculations.
B32: Assumptions | C32: General | D32: Past 5 years revenue growth trend (FY2021–FY2025) used as primary driver to forecast revenue. Other income forecasted using 5-year historical average as a percentage of revenue.
B33: Assumptions | C33: Perpetual Growth Rate | D33: A mild tapering rate of 6% has been assumed considering stable defence budget allocations, strong order book visibility, and Government of India's Atmanirbhar Bharat push for domestic defence production.
B34: Forecasts & Supporting Schedules | C34: Receivable / Payable / Inventory Days | D34: Past 4-year average trend used to forecast working capital days. FY2021 has been excluded from the average due to COVID-19 distortion in receivable and inventory days relative to the normal operating cycle.
B35: Forecasts & Supporting Schedules | C35: Cost Drivers | D35: Historical 5-year average growth rates used to forecast future costs. For COGS and salaries, past 3-year trend preferred to reduce pandemic-period distortion in FY2021–FY2022.
B36: Forecasts & Supporting Schedules | C36: Depreciation & Interest | D36: Depreciation taken as % of opening gross PP&E. Interest taken as % of revenue. Depreciation rate assumed to increase by ~1% every 2 years reflecting BEL's ongoing capacity expansion across its nine manufacturing units.
B37: Forecasts & Supporting Schedules | C37: Capex | D37: BEL's historical capex growth ranges from 15–25% YoY driven by modernisation of manufacturing facilities and new product development. Capex assumed to grow at minimum 8% per year on a conservative basis, consistent with India's defence indigenisation roadmap and BEL's expanding order book.
B38: Forecasts & Supporting Schedules | C38: Dividend Payout | D38: FY2021 excluded from average payout ratio calculation due to COVID-19-related atypical dividend behaviour. BEL has maintained a consistent payout ratio of ~34–36% in FY2022–FY2025, which has been used as the forecast base.
B39: Forecasts & Supporting Schedules | C39: Tax Rate | D39: Effective tax rate assumed to remain stable at ~25.2% with a marginal increase of 0.5% every two years in line with potential changes in corporate tax policy.
B40: Ratio Analysis | C40: General | D40: Ratio interpretations designed for presentation clarity. Key ratios include ROCE, ROE, Asset Turnover, Current Ratio, Debt-to-Equity, and Order Book-to-Revenue coverage ratio, with expandable commentary for each.

Sheet Historial IS
E1: Bharat Electronics Ltd
B2: Historical Financial Information
A3: # | B3: INCOME STATEMENT | K3: ='Data Sheet'!G16 -> 44286 | L3: ='Data Sheet'!H16 -> 44651 | M3: ='Data Sheet'!I16 -> 45016 | N3: ='Data Sheet'!J16 -> 45382 | O3: ='Data Sheet'!K16 -> 45747
B4: Revenue from Operations | K4: 1406383 | L4: 1531376 | M4: 1764620 | N4: 2016939 | O4: 2365801
B5: Other Income | K5: 12610 | L5: 23359 | M5: 36002 | N5: 75584 | O5: 76759
B6: Total Income ( I + II ) | K6: =SUM(K4:K5) -> 1418993 | L6: =SUM(L4:L5) -> 1554735 | M6: =SUM(M4:M5) -> 1800622 | N6: =SUM(N4:N5) -> 2092523 | O6: =SUM(O4:O5) -> 2442560
B8: EXPENSES
B9: Cost of Materials Consumed | K9: -668520 | L9: -809634 | M9: -937844 | N9: -1049762 | O9: -1256140
B10: Purchases of Stock - in - Trade | K10: -123321 | L10: -105349 | M10: -82785 | N10: -62886 | O10: -43041
B11: Changes in Inventories of Finished Goods , Stock - in - Trade , Work - in - Progress and Scrap | K11: -12933 | L11: -27697 | M11: -39745 | N11: -56057 | O11: -81083
B12: Employee Benefits Expense | K12: -194068 | L12: -210939 | M12: -229773 | N12: -246670 | O12: -273436
B13: Finance Costs | K13: -608 | L13: -485 | M13: -1479 | N13: -702 | O13: -961
B14: Depreciation and Amortization Expense | K14: -36633 | L14: -38018 | M14: -40787 | N14: -41243 | O14: -43558
B15: Other Expenses | K15: -111421 | L15: -99263 | M15: -149211 | N15: -213861 | O15: -197508 | T15: =T11+T12 -> 0
B16: Total Gross Expenses | K16: =SUM(K9:K15) -> -1147504 | L16: =SUM(L9:L15) -> -1291385 | M16: =SUM(M9:M15) -> -1481624 | N16: =SUM(N9:N15) -> -1671181 | O16: =SUM(O9:O15) -> -1895727
B17: Less : Expenses relating to Capital and Other Accounts | K17: 0 | L17: 0 | M17: 0 | N17: 0 | O17: 0
B18: Total expenses ( IV ) | K18: =K16 -> -1147504 | L18: =L16 -> -1291385 | M18: =M16 -> -1481624 | N18: =N16 -> -1671181 | O18: =O16 -> -1895727
B20: Profit / ( loss ) before tax | K20: =K6-K18 -> 2566497 | L20: =L6-L18 -> 2846120 | M20: =M6-M18 -> 3282246 | N20: =N6-N18 -> 3763704 | O20: =O6-O18 -> 4338287
B22: Tax expense :
B23: ( 1 ) Current Tax | K23: -82493 | L23: -91052 | M23: -87446 | N23: -144959 | O23: -176135
B24: ( 2 ) Earlier Year Tax Refund / Liability | K24: -2492 | L24: 0 | M24: -2001 | N24: -6890 | O24: 274
B25: ( 3 ) Deferred Tax | K25: 6938 | L25: -10165 | M25: 12376 | N25: -6613 | O25: 3765
B26: Total tax exp | K26: =SUM(K23:K25) -> -78047 | L26: =SUM(L23:L25) -> -101217 | M26: =SUM(M23:M25) -> -77071 | N26: =SUM(N23:N25) -> -158462 | O26: =SUM(O23:O25) -> -172096
B28: Profit ( Loss ) for the period from Continuing Operations ( IX - X ) | K28: =K20-K26 -> 2644544 | L28: =L20-L26 -> 2947337 | M28: =M20-M26 -> 3359317 | N28: =N20-N26 -> 3922166 | O28: =O20-O26 -> 4510383
B29: Profit / ( loss ) from Discontinued Operations | K29: 0 | L29: 0 | M29: 0 | N29: 0 | O29: 0
B30: Tax expense of Discontinued Operations | K30: 0 | L30: 0 | M30: 0 | N30: 0 | O30: 0
B31: Profit / ( loss ) from Discontinued Operations ( after tax ) ( XII - XIII ) | K31: 0 | L31: 0 | M31: 0 | N31: 0 | O31: 0
B32: Profit / ( loss ) for the period ( XI + XIV ) | K32: =SUM(K28:K31) -> 2644544 | L32: =SUM(L28:L31) -> 2947337 | M32: =SUM(M28:M31) -> 3359317 | N32: =SUM(N28:N31) -> 3922166 | O32: =SUM(O28:O31) -> 4510383
B34: KPIs | K34: =K3 -> 44286 | L34: =L3 -> 44651 | M34: =M3 -> 45016 | N34: =N3 -> 45382 | O34: =O3 -> 45747
B35: Revenue % (y-o-y) | K35: 0 | L35: =(L4/K4)-1 -> 0.088875505 | M35: =(M4/L4)-1 -> 0.15231008 | N35: =(N4/M4)-1 -> 0.14298773 | O35: =(O4/N4)-1 -> 0.17296606
B36: GP% | K36: ='Ratio analysis'!C15 -> 0.42777039 | L36: ='Ratio analysis'!D15 -> 0.3844229 | M36: ='Ratio analysis'!E15 -> 0.39909216 | N36: ='Ratio analysis'!F15 -> 0.42055511 | O36: ='Ratio analysis'!G15 -> 0.41657646
B37: EBITDA% | K37: ='Forecasts & support schedules'!D33/'Forecasts & support schedules'!D27 -> 0.21055431 | L37: ='Forecasts & support schedules'!E33/'Forecasts & support schedules'!E27 -> 0.18185867 | M37: ='Forecasts & support schedules'!F33/'Forecasts & support schedules'!F27 -> 0.1843241 | N37: ='Forecasts & support schedules'!G33/'Forecasts & support schedules'!G27 -> 0.19222346 | O37: ='Forecasts & support schedules'!H33/'Forecasts & support schedules'!H27 -> 0.21751322
B38: EBIT % | K38: ='Forecasts & support schedules'!D35/'Forecasts & support schedules'!D27 -> 0.18450664 | L38: ='Forecasts & support schedules'!E35/'Forecasts & support schedules'!E27 -> 0.15703263 | M38: ='Forecasts & support schedules'!F35/'Forecasts & support schedules'!F27 -> 0.16121035 | N38: ='Forecasts & support schedules'!G35/'Forecasts & support schedules'!G27 -> 0.17177515 | O38: ='Forecasts & support schedules'!H35/'Forecasts & support schedules'!H27 -> 0.1991017
B39: NP % | K39: ='Forecasts & support schedules'!D44/'Forecasts & support schedules'!D27 -> 0.13754575 | L39: ='Forecasts & support schedules'!E44/'Forecasts & support schedules'!E27 -> 0.10587406 | M39: ='Forecasts & support schedules'!F44/'Forecasts & support schedules'!F27 -> 0.13709864 | N39: ='Forecasts & support schedules'!G44/'Forecasts & support schedules'!G27 -> 0.13033612 | O39: ='Forecasts & support schedules'!H44/'Forecasts & support schedules'!H27 -> 0.15839752
B40: Asset Turnover | K40: ='Ratio analysis'!C25 -> 0.44365219 | L40: ='Ratio analysis'!D25 -> 0.44130245 | M40: ='Ratio analysis'!E25 -> 0.47044319 | N40: ='Ratio analysis'!F25 -> 0.50197991 | O40: ='Ratio analysis'!G25 -> 0.57940074

Sheet Historical BS
E1: Bharat Electronics Ltd
B2: Historical Financial Information
A3: # | B3: BALANCE SHEET | K3: ='Data Sheet'!G16 -> 44286 | L3: ='Data Sheet'!H16 -> 44651 | M3: ='Data Sheet'!I16 -> 45016 | N3: ='Data Sheet'!J16 -> 45382 | O3: ='Data Sheet'!K16 -> 45747
A4: v
B5: ASSETS
B6: Non - current assets
B7: ( a ) Property , Plant and Equipment | K7: 248550 | L7: 250937 | M7: 269431 | N7: 278847 | O7: 320453
B8: ( b ) Capital work - in - progress | K8: 39747 | L8: 44593 | M8: 36123 | N8: 45642 | O8: 47698
B9: ( c ) Investment Property | K9: 8 | L9: 7 | M9: 6 | N9: 4 | O9: 4
B10: ( d ) Goodwill | K10: 0 | L10: 0 | M10: 0 | N10: 0 | O10: 0
B11: ( e ) Other Intangible assets | K11: 16656 | L11: 16582 | M11: 26849 | N11: 24670 | O11: 21466
B12: ( f ) Intangible Assets under Development | K12: 48521 | L12: 56011 | M12: 49371 | N12: 43730 | O12: 57482
B13: ( g ) Investments accounted for using the Equity Method | K13: 18989 | L13: 23292 | M13: 20073 | N13: 15157 | O13: 16136
B14: ( h ) Financial Assets
B15: ( i ) Investments | K15: 111605 | L15: 133910 | M15: 44926 | N15: 53066 | O15: 58161
B16: ( ii ) Trade Receivables | K16: 0 | L16: 0 | M16: 0 | N16: 0 | O16: 0
B17: ( iii ) Contract Assets | K17: 0 | L17: 0 | M17: 0 | N17: 0 | O17: 0
B18: ( iv ) Loans | K18: 736 | L18: 728 | M18: 656 | N18: 703 | O18: 663
B19: ( v ) Other Financial Assets | K19: 2871 | L19: 2417 | M19: 2045 | N19: 1883 | O19: 2415
B20: ( i ) Deferred tax Assets ( Net ) | K20: 46346 | L20: 62094 | M20: 50372 | N20: 57468 | O20: 53484
B21: ( j ) Inventories | K21: 3938 | L21: 2734 | M21: 587 | N21: 0 | O21: 0
B22: ( k ) Other Non - Current Assets | K22: 39669 | L22: 68382 | M22: 43904 | N22: 25200 | O22: 19436
B23: Total non - current assets | K23: =SUM(K7:K22) -> 577636 | L23: =SUM(L7:L22) -> 661687 | M23: =SUM(M7:M22) -> 544343 | N23: =SUM(N7:N22) -> 546370 | O23: =SUM(O7:O22) -> 597398
B25: Current assets
B26: ( a ) Inventories | K26: 496798 | L26: 559190 | M26: 644804 | N26: 744689 | O26: 911898
B27: ( b ) Financial Assets
B28: ( i ) Investments
B29: ( ii ) Trade receivables | K29: 656199 | L29: 610809 | M29: 703348 | N29: 739238 | O29: 911637
B30: ( iii ) Contract Assets
B31: ( iv ) Cash and Cash Equivalents | K31: 304290 | L31: 130086 | M31: 394569 | N31: 120632 | O31: 71345
B32: Bank Balances other than Cash and Cash Equivalents | K32: 203086 | L32: 626288 | M32: 416589 | N32: 985027 | O32: 883165
B33: ( vi ) Loans | K33: 152 | L33: 148 | M33: 172 | N33: 141 | O33: 147
B34: ( vii ) Other Financial Assets | K34: 6066 | L34: 10254 | M34: 20342 | N34: 29440 | O34: 24133
B35: ( c ) Current Tax Assets ( Net ) | K35: 13364 | L35: 14474 | M35: 40314 | N35: 44961 | O35: 35362
B36: ( d ) Other Currents Assets | K36: 691376 | L36: 778122 | M36: 784636 | N36: 742170 | O36: 648101
B37: Total current assets | K37: =SUM(K26:K36) -> 2371331 | L37: =SUM(L26:L36) -> 2729371 | M37: =SUM(M26:M36) -> 3004774 | N37: =SUM(N26:N36) -> 3406298 | O37: =SUM(O26:O36) -> 3485788
B39: Assets held for Sale | K39: 0 | L39: 0 | M39: 81.1 | N39: 81.1 | O39: 0
B40: Total Assets | K40: =SUM(K23,K37,K39) -> 2948967 | L40: =SUM(L23,L37,L39) -> 3391058 | M40: =SUM(M23,M37,M39) -> 3549198.1 | N40: =SUM(N23,N37,N39) -> 3952749.1 | O40: =SUM(O23,O37,O39) -> 4083186
B42: EQUITY AND LIABILITIES
B43: Equity
...

Sheet Historical CF
B1: Bharat Electronics Ltd
B2: Historical Financial Information
A3: # | B3: CASH FLOW STATEMENT | F3: ='Historical BS'!K3 -> 44286 | G3: ='Historical BS'!L3 -> 44651 | H3: ='Historical BS'!M3 -> 45016 | I3: ='Historical BS'!N3 -> 45382 | J3: ='Historical BS'!O3 -> 45747
B5: Cash flow from Operating Activities
B6: Profit after share of associate (before exceptional items & tax) | F6: 297220 | G6: 321200 | H6: 396880 | I6: 530834 | J6: 713453
B7: Adjustments for:
B8: Depreciation and amortisation expense | F8: 38732 | G8: 40113 | H8: 42882 | I8: 44320 | J8: 46738
B9: Provision for intangible assets under development | F9: 7213 | G9: 0 | H9: 544 | I9: 9666 | J9: 0
B10: Intangible assets under development charged off | F10: 75 | G10: 0 | H10: 1950 | I10: 0 | J10: 129
B11: Capital WIP charged off | F11: 1468 | G11: 0 | H11: 0 | I11: 0 | J11: 0
B12: Provision Others – Contract costs | F12: 0 | G12: 0 | H12: 4180 | I12: 2 | J12: 0
B13: Prov. for doubtful debts, liq. damages & disallowances (net) | F13: 0 | G13: 0 | H13: 37536 | I13: 83118 | J13: 0
B14: Provision for doubtful advances, claims (net of withdrawal) | F14: 0 | G14: 0 | H14: 0 | I14: 1913 | J14: 0
B15: Provision for performance warranty (net) | F15: 0 | G15: 0 | H15: 0 | I15: 16852 | J15: 0
B16: Provision for onerous contract (net) | F16: 0 | G16: 0 | H16: 0 | I16: 3132 | J16: 0
B17: Provision for obsolete/redundant materials (net) | F17: 0 | G17: 0 | H17: 0 | I17: 7235 | J17: 0
B18: Corporate social responsibility | F18: 4711 | G18: 5348 | H18: 5770 | I18: 0 | J18: 0
B19: Transfer from government grants | F19: -1736 | G19: -1713 | H19: -1665 | I19: -1657 | J19: -1647
... B23: Profit on sale of property, plant & equipment | F23: -121 | G23: -45 | H23: -152 | I23: -702 | J23: -255
B24: Operating Profit Before Working Capital Changes | F24: =SUM(F6:F23) -> 342149 | G24: =SUM(G6:G23) -> 347763 | H24: =SUM(H6:H23) -> 463332 | I24: =SUM(I6:I23) -> 638232 | J24: =SUM(J6:J23) -> 697152
B26: Adjustments for :
B27: Increase / (Decrease) due to
B28: Trade receivables | F28: 16203 | G28: 45390 | H28: -92539 | I28: -119008 | J28: -172399
B29: Loans | F29: 4079 | G29: 12 | H29: 48 | I29: -16 | J29: 34
B30: Other financial assets | F30: -2713 | G30: -3456 | H30: -9456 | I30: 4565 | J30: 278
B31: Other assets | F31: -90272 | G31: -115459 | H31: 13784 | I31: 59255 | J31: 99836
B32: Inventories | F32: -99651 | G32: -61188 | H32: -83467 | I32: -106533 | J32: -167209
B33: Trade payables | F33: 84886 | G33: 7045 | H33: -3889 | I33: 37556 | J33: -36754
B34: Other financial liabilities | F34: 7891 | G34: 6093 | H34: 32025 | I34: 3351 | J34: 6496
B35: Provisions | F35: 14650 | G35: 26755 | H35: -97882 | I35: -8694 | J35: -1026
B36: Other liabilities | F36: 297706 | G36: 260611 | H36: 48999 | I36: 99078 | J36: -200282
B37: Current tax assets | F37: -12299 | G37: -12415 | H37: -15411 | I37: 0 | J37: 0
B38: Cash Generated from Operations | F38: =SUM(F24,F28:F37) -> 562629 | G38: =SUM(G24,G28:G37) -> 501151 | H38: =SUM(H24,H28:H37) -> 255544 | I38: =SUM(I24,I28:I37) -> 607786 | J38: =SUM(J24,J28:J37) -> 226126
B39: Income taxes paid (net) | F39: -53307 | G39: -80429 | H39: -91322 | I39: -141837 | J39: -167464
B40: Cash Flow Before Exceptional Items | F40: =SUM(F38:F39) -> 509322 | G40: =SUM(G38:G39) -> 420722 | H40: =SUM(H38:H39) -> 164222 | I40: =SUM(I38:I39) -> 465949 | J40: =SUM(J38:J39) -> 58662
B41: Exceptional items | F41: 0 | G41: 0 | H41: 0 | I41: 0 | J41: 0
B42: Net Cash ( used in ) / generated from Operating Activities ( A ) | F42: =F40+F41 -> 509322 | G42: =G40+G41 -> 420722 | H42: =H40+H41 -> 164222 | I42: =I40+I41 -> 465949 | J42: =J40+J41 -> 58662
B44: Cash flow from Investing Activities
B45: Purchase of PPE and other intangible assets | F45: -46925 | G45: -55456 | H45: -59045 | I45: -65253 | J45: -101128
B46: Receipt / Less: Receipt of grant | F46: 0 | G46: 0 | H46: 228 | I46: 10 | J46: 7
...

Sheet Summary
B1: Bharat Electronics Ltd
B3: Football Field Data
D5: Comps | E5: DCF | F5: 52-week hi/lo | G5: market consensus
B7: High | D7: =MAX('Comps valution'!I21:I23) -> 4585.6398 | E7: 219 | F7: 473 | G7: 593
B8: High | D8: =D7 -> 4585.6398 | E8: 219 | F8: =F7 -> 473 | G8: =G7 -> 593
B9: Low | D9: =MIN('Comps valution'!I21:I23) -> 128.47453 | E9: 65 | F9: 253 | G9: 263
B10: Low | D10: =D9 -> 128.47453 | E10: 65 | F10: =F9 -> 253 | G10: =G9 -> 263
B12: Valuation Summary

Sheet Beta
D1: Bharat Electronics Ltd
B2: Regression beta
C4: Index | D4: % Change | E4: Stock | F4: % Change
B5: Date | C5: Close Price | D5: Monthly | E5: Close Price | F5: Monthly
B6: 44317 | C6: 1505526495 | E6: 45.37
B7: 44348 | C7: 1186761072 | D7: =C7/C6-1 -> -0.2117302 | E7: 55.55 | F7: =E7/E6-1 -> 0.22437734
B8: 44378 | C8: 588864033 | D8: =C8/C7-1 -> -0.50380574 | E8: 57.62 | F8: =E8/E7-1 -> 0.037263726
B9: 44409 | C9: 573740100 | D9: =C9/C8-1 -> -0.025683234 | E9: 58.25 | F9: =E9/E8-1 -> 0.010933704
B10: 44440 | C10: 472297200 | D10: =C10/C9-1 -> -0.17680985 | E10: 63.33 | F10: =E10/E9-1 -> 0.0872103
B11: 44470 | C11: 399386091 | D11: =C11/C10-1 -> -0.15437548 | E11: 64.95 | F11: =E11/E10-1 -> 0.025580294
B12: 44501 | C12: 409649820 | D12: =C12/C11-1 -> 0.025698764 | E12: 63.97 | F12: =E12/E11-1 -> -0.01508853
B13: 44531 | C13: 367604007 | D13: =C13/C12-1 -> -0.10263843 | E13: 65.92 | F13: =E13/E12-1 -> 0.030483039
B14: 44562 | C14: 408048816 | D14: =C14/C13-1 -> 0.11002276 | E14: 65.84 | F14: =E14/E13-1 -> -0.0012135922
B15: 44593 | C15: 382511754 | D15: =C15/C14-1 -> -0.06258335 | E15: 66.08 | F15: =E15/E14-1 -> 0.0036452005
B16: 44621 | C16: 592569945 | D16: =C16/C15-1 -> 0.54915487 | E16: 66.69 | F16: =E16/E15-1 -> 0.0092312349
B17: 44652 | C17: 756720162 | D17: =C17/C16-1 -> 0.27701408 | E17: 76.02 | F17: =E17/E16-1 -> 0.13990103
B18: 44682 | C18: 344665149 | D18: =C18/C17-1 -> -0.5445276 | E18: 74.81 | F18: =E18/E17-1 -> -0.015916864
... B52: 45717 | C52: 434656933 | D52: =C52/C51-1 -> -0.083965369 | E52: 297.7 | F52: =E52/E51-1 -> 0.22364257

Sheet Market Data
D1: Bharat Electronics Ltd
B2: Equity Market Return
C4: Index
B5: Date | C5: Close Price
B6: 42072 | C6: 8756.75 | E6: Yearfrac | F6: =YEARFRAC(B6,B2714) -> 10.991667
B7: 42073 | C7: 8712.05
B8: 42074 | C8: 8699.95 | E8: Market Return | F8: =_xlfn.RRI(F6,C6,C2714) -> 0.097920997
B9: 42075 | C9: 8776
B10: 42076 | C10: 8647.75
B11: 42079 | C11: 8633.15
B12: 42080 | C12: 8723.3
B13: 42081 | C13: 8685.9
B14: 42082 | C14: 8634.65
B15: 42083 | C15: 8570.9
B16: 42086 | C16: 8550.9
B17: 42087 | C17: 8542.95
B18: 42088 | C18: 8530.8
B19: 42089 | C19: 8342.15
B20: 42090 | C20: 8341.4
... B2714: 46087 | C2714: 24450.45

Sheet Comps valution
B1: Bharat Electronics Ltd
B3: Comps Valuation
E5: Market Data | L5: Financial Data | P5: Valuation
E6: Price | F6: Shares | G6: Market Cap | H6: Debt | I6: Cash | J6: EV | L6: Sales | M6: EBITDA | N6: Earnings | P6: EV/Sales | Q6: EV/EBITDA | R6: P/E
B7: Company Name | C7: Ticker | E7: (₹/share) | F7: number | G7: ₹ MM | I7: & Equivalents | J7: ₹ MM | L7: ₹ MM | M7: ₹ MM | N7: ₹ MM | P7: x | Q7: x | R7: x
B8: Hindustan Aeronautics | C8: HAL | E8: 4023.7 | F8: 66.88 | G8: 2690466 | H8: 114 | I8: 444714 | J8: 2245866 | L8: 328463 | M8: 12169.77 | N8: 8896.11 | P8: =J8/L8 -> 6.8375007 | Q8: 16.95 | R8: 30.24
B9: Bharat Dynamics | C9: BDL | E9: 1356.7 | F9: 36.66 | G9: 4965398 | H9: 12 | I9: 418164 | J9: 4547358 | L9: 37386 | M9: 469.7 | N9: 579.92 | P9: =J9/L9 -> 121.63264 | Q9: 52.19 | R9: 85.62
B10: Garden Reach Shipbuilders | C10: GRSE | E10: 2523.2 | F10: 11.46 | G10: 2892237 | H10: 320 | I10: 315730 | J10: 2579705 | L10: 65250 | M10: 756 | N10: 688.99 | P10: =J10/L10 -> 39.535709 | Q10: 26.37 | R10: 41.98
B11: Data Patterns | C11: DATAPATT | E11: 3491.2 | F11: 5.6 | G11: 1953988 | H11: 58 | I11: 17334 | J11: 1947235 | L11: 9761 | M11: 77.58 | N11: 247.07 | P11: =J11/L11 -> 199.49134 | Q11: 53.56 | R11: 78.35
B12: Zen Technologies | C12: ZENTEC | E12: 1426.8 | F12: 9.03 | G12: 1287713 | H12: 180 | I12: 83273 | J12: 1206235 | L12: 8346 | M12: 371.5 | N12: 284.44 | P12: =J12/L12 -> 144.52852 | Q12: 28.67 | R12: 49.09
B13: MTAR Technologies | C13: MTAR | E13: 3782.2 | F13: 3.08 | G13: 1163275 | H13: 1865 | I13: 17810 | J13: 1180139 | L13: 7532 | M13: 120.9 | N13: 65.19 | P13: =J13/L13 -> 156.68335 | Q13: 78.11 | R13: 171.37
B15: Average | P15: =AVERAGE(P8:P13) -> 111.45151 | Q15: =AVERAGE(Q8:Q13) -> 42.641667 | R15: =AVERAGE(R8:R13) -> 76.108333
B16: Median | P16: =MEDIAN(P8:P13) -> 133.08058 | Q16: =MEDIAN(Q8:Q13) -> 40.43 | R16: =MEDIAN(R8:R13) -> 63.72
B18: Bharat Electronics | C18: BEL | E18: 468.45 | F18: 730.98 | G18: 3424265 | H18: 589 | I18: 8911 | J18: 3343689 | L18: 265352 | M18: 2117 | N18: 5962.93 | P18: =J18/L18 -> 12.600956 | Q18: =J18/M18 -> 1579.4469 | R18: 57.4
B20: Metric | C20: Comps | E20: EV | F20: Net Debt | G20: Equity Value | H20: Shares | I20: Share Price | J20: Recommendation
B21: EV/Revenue | C21: =P16 -> 133.08058 | E21: =J18 -> 3343689 | F21: =H18-I18 -> -8322 | G21: =E21-F21 -> 3352011 | H21: =$F$18 -> 730.98 | I21: =G21/H21 -> 4585.6398 | J21: BUY
B22: EV/EBITDA | C22: =Q16 -> 40.43 | E22: =C22*M18 -> 85590.31 | F22: -8322 | G22: =E22-F22 -> 93912.31 | H22: =$F$18 -> 730.98 | I22: =G22/H22 -> 128.47453 | J22: BUY
B23: P/E | C23: =R16 -> 63.72 | E23: =F23+G23 -> 371635.9 | F23: -8322 | G23: =C23*N18 -> 379957.9 | H23: =$F$18 -> 730.98 | I23: =G23/H23 -> 519.79247 | J23: BUY
G28: 9

Sheet WACC
C1: Bharat Electronics Ltd
B3: Weighted-Average Cost of Capital (WACC)
B4: All Amounts Denominated in INR MM Unless Otherwise Stated
B7: Comparable Companies Beta
I8: Equity | J8: Total | K8: Debt/ | L8: Debt/ | M8: Tax | N8: Levered | O8: Unlevered
I9: Value | J9: Debt | K9: Equity | L9: Capital | M9: Rate % | N9: Beta | O9: Beta
B10: Hindustan Aeronautics | I10: ='Comps valution'!G8 -> 2690466 | J10: ='Comps valution'!H8 -> 114 | K10: =J10/I10 -> 4.2371842e-05 | L10: =J10/(I10+J10) -> 4.2370047e-05 | M10: 0.255 | N10: 0.002 | O10: 1.05
B11: Bharat Dynamics | I11: ='Comps valution'!G9 -> 4965398 | J11: ='Comps valution'!H9 -> 12 | K11: =J11/I11 -> 2.4167247e-06 | L11: =J11/(I11+J11) -> 2.4167189e-06 | M11: 0.258 | N11: 0.001 | O11: 0.85
B12: Garden Reach Shipbuilders | I12: ='Comps valution'!G10 -> 2892237 | J12: ='Comps valution'!H10 -> 320 | K12: 0.1 | L12: =J12/(I12+J12) -> 0.00011062876 | M12: 0.259 | N12: 0.001 | O12: 0.9
B13: Data Patterns | I13: ='Comps valution'!G11 -> 1953988 | J13: ='Comps valution'!H11 -> 58 | K13: 0.1 | L13: =J13/(I13+J13) -> 2.9682003e-05 | M13: 0.254 | N13: 0.012 | O13: 1.19
B14: Zen Technologies | I14: ='Comps valution'!G12 -> 1287713 | J14: ='Comps valution'!H12 -> 180 | K14: 0.1 | L14: =J14/(I14+J14) -> 0.00013976316 | M14: 0.259 | N14: 0.006 | O14: 0.75
B15: MTAR Technologies | I15: ='Comps valution'!G13 -> 1163275 | J15: ='Comps valution'!H13 -> 1865 | K15: 0.25 | L15: =J15/(I15+J15) -> 0.001600666 | M15: 0.255 | N15: 0.015 | O15: 0.79
B17: Average | K17: =AVERAGE(K10:K15) -> 0.091674131 | L17: =AVERAGE(L10:L15) -> 0.00032092112 | M17: =AVERAGE(M10:M15) -> 0.25666667 | N17: =AVERAGE(N10:N15) -> 0.0061666667 | O17: =AVERAGE(O10:O15) -> 0.92166667
B18: Median | K18: =MEDIAN(K10:K15) -> 0.1 | L18: =MEDIAN(L10:L15) -> 7.6499404e-05 | M18: =MEDIAN(M10:M15) -> 0.2565 | N18: =MEDIAN(N10:N15) -> 0.004 | O18: =MEDIAN(O10:O15) -> 0.875
B20: Hindustan Aeronautics Limited | I20: ='Comps valution'!G18 -> 3424265 | J20: ='Comps valution'!H18 -> 589
B22: WACC Calculation
B24: Target Capital Structure
B26: Proportion of Debt | G26: =L18 -> 7.6499404e-05
B27: Proportion of Equity | G27: =1-G26 -> 0.9999235
B29: Current Capital Structure
B30: Market Cap | G30: =I20 -> 3424265
B31: Total Debt | G31: =J20 -> 589
B32: Debt / Equity | G32: 0.0002
B34: Cost of Debt
B35: Pre-Tax Cost of Debt | G35: 0.0819
B36: Tax Rate | G36: 0.255
B37: After-Tax Cost of Debt | G37: 0.061
B39: Cost of Equity (CAPM)
B40: Risk Free Rate | G40: 0.0719
B41: Equity Market Return | G41: 0.135
B42: Equity Risk Premium | G42: 0.0631
B43: Unlevered Beta (median comps) | G43: =N17 -> 0.0061666667
B44: Levered Beta (re-levered) | G44: =O17 -> 0.92166667
B45: Cost of Equity | G45: 0.1271
B48: WACC
B49: Weighted Average Cost of Capital | G49: =(G45*99.98%)+(WACC!G37*(1-WACC!G36)*0.02%) -> 0.12708367

Sheet Sheet1

Sheet Forecasts & support schedules
B1: Bharat Electronics Ltd
A3: Financial Statements & DCF Analysis | D3: HISTORICAL PERIOD | I3: FORECASTED PERIOD
D5: ='Historical CF'!F3 -> 44286 | E5: ='Historical CF'!G3 -> 44651 | F5: ='Historical CF'!H3 -> 45016 | G5: ='Historical CF'!I3 -> 45382 | H5: ='Historical CF'!J3 -> 45747 | I5: 46221 | J5: 46587 | K5: 46954 | L5: 47320 | M5: 47686 | N5: 48052 | O5: 48418 | P5: 48784 | Q5: 49150 | R5: 49516
B6: Master Check
A8: Ratios & Assumptions
B10: LIVE SCENARIO
B11: Revenue Growth | C11: % | E11: =E27/D27-1 -> 0.088875505 | F11: =F27/E27-1 -> 0.15231008 | G11: =G27/F27-1 -> 0.14298773 | H11: =H27/G27-1 -> 0.17296606 | I11: =Assumptions!AO12 -> 0.18 | J11: =Assumptions!AP12 -> 0.17 | K11: =Assumptions!AQ12 -> 0.17 | L11: =Assumptions!AR12 -> 0.16 | M11: =Assumptions!AS12 -> 0.15 | N11: =Assumptions!AT12 -> 0.145 | O11: =Assumptions!AU12 -> 0.14 | P11: =Assumptions!AV12 -> 0.135 | ... R11: =Assumptions!AX12 -> 0.125
B12: Cost of Goods Sold (% of Revenue) | C12: % | D12: =-D28/D27 -> 0.57222961 | E12: =-E28/E27 -> 0.6155771 | F12: =-F28/F27 -> 0.60090784 | G12: =-G28/G27 -> 0.57944489 | H12: =-H28/H27 -> 0.58342354 | I12: =AVERAGE(F12:H12) -> 0.58792543 | J12: =I12 -> 0.58792543 | K12: =J12 -> 0.58792543 | L12: =K12 -> 0.58792543 | M12: =L12 -> 0.58792543 | N12: =M12 -> 0.58792543 | O12: =N12 -> 0.58792543 | P12: =O12 -> 0.58792543 | Q12: =P12 -> 0.58792543 | R12: =Q12 -> 0.58792543
B13: Salaries and benefits (% of Revenue) | C13: % | D13: =-D31/D27 -> 0.13799086 | E13: =-E31/E27 -> 0.13774475 | F13: =-F31/F27 -> 0.13021104 | G13: =-G31/G27 -> 0.12229919 | H13: =-H31/H27 -> 0.11557861 | I13: =H13 -> 0.11557861 | J13: =I13 -> 0.11557861 | K13: =J13 -> 0.11557861 | L13: =K13 -> 0.11557861 | M13: =L13 -> 0.11557861 | N13: =M13 -> 0.11557861 | O13: =N13 -> 0.11557861 | P13: =O13 -> 0.11557861 | ... R13: =Q13 -> 0.11557861
B14: Other operating Expenses (% of Revenue) | C14: % | D14: =-D22/D27 -> -4.0233353e-06 | E14: =-E22/E27 -> -3.985064e-06 | F14: =-F22/F27 -> -3.7115254e-06 | G14: =-G22/G27 -> -3.586196e-06 | H14: =-H22/H27 -> -3.1205824e-06 | I14: =H14 -> -3.1205824e-06 | J14: =I14 -> -3.1205824e-06 | K14: =J14 -> -3.1205824e-06 | L14: =K14 -> -3.1205824e-06 | M14: =L14 -> -3.1205824e-06 | N14: =M14 -> -3.1205824e-06 | O14: =N14 -> -3.1205824e-06 | P14: =O14 -> -3.1205824e-06 | ... R14: =Q14 -> -3.1205824e-06
B15: Depreciation & Amortization Expenses (% of PP&E) | C15: % | D15: =-D34/D27 -> 0.02604767 | E15: =-E34/E27 -> 0.024826039 | F15: =-F34/F27 -> 0.023113758 | G15: =-G34/G27 -> 0.020448313 | H15: =-H34/H27 -> 0.018411523 | I15: =H15+1% -> 0.028411523 | J15: =I15 -> 0.028411523 | K15: =J15+1% -> 0.038411523 | L15: =K15 -> 0.038411523 | M15: =L15+1% -> 0.048411523 | N15: =M15 -> 0.048411523 | O15: =N15+1% -> 0.058411523 | P15: =O15 -> 0.058411523 | Q15: =P15+1% -> 0.068411523 | R15: =Q15 -> 0.068411523
B16: Interest (% of revenue) | C16: % | D16: =-D36/D27 -> 0.00043231467 | E16: =-E36/E27 -> 0.00031670863 | F16: =-F36/F27 -> 0.00083814079 | G16: =-G36/G27 -> 0.00034805217 | H16: =-H36/H27 -> 0.00040620492 | I16: =H16 -> 0.00040620492 | J16: =I16 -> 0.00040620492 | K16: =J16 -> 0.00040620492 | L16: =K16 -> 0.00040620492 | M16: =L16 -> 0.00040620492 | N16: =M16 -> 0.00040620492 | O16: =N16 -> 0.00040620492 | P16: =O16 -> 0.00040620492 | ... R16: =Q16 -> 0.00040620492
B17: Other Income (Expenses) (% of Revenue) | C17: % | D17: =D37/D27 -> 0.0089662631 | E17: =E37/E27 -> 0.015253602 | F17: =F37/F27 -> 0.020402126 | G17: =G37/G27 -> 0.037474609 | H17: =H37/H27 -> 0.032445248 | I17: =H17 -> 0.032445248 | J17: =I17 -> 0.032445248 | K17: =J17 -> 0.032445248 | L17: =K17 -> 0.032445248 | M17: =L17 -> 0.032445248 | N17: =M17 -> 0.032445248 | O17: =N17 -> 0.032445248 | P17: =O17 -> 0.032445248 | ... R17: =Q17 -> 0.032445248
B18: Tax Rate (% of Earnings before Tax) | C18: % | D18: =D45/D27 -> 0 | E18: =E45/E27 -> 0 | F18: =F45/F27 -> 0 | G18: =G45/G27 -> 0 | H18: =H45/H27 -> 0 | I18: =H18 -> 0 | J18: =I18 -> 0 | K18: =J18 -> 0 | L18: =K18 -> 0 | M18: =L18 -> 0 | N18: =M18 -> 0 | O18: =N18 -> 0 | P18: =O18 -> 0 | ... R18: =Q18 -> 0
B20: Inventory | C20: Days | D20: =-D70/D28*365 -> 225.31949 | E20: =-E70/E28*365 -> 216.51499 | F20: =-F70/F28*365 -> 221.95325 | G20: =-G70/G28*365 -> 232.57493 | H20: =-H70/H28*365 -> 241.14428 | I20: =H20 -> 241.14428 | J20: =I20 -> 241.14428 | K20: =J20 -> 241.14428 | L20: =K20 -> 241.14428 | M20: =L20 -> 241.14428 | N20: =M20 -> 241.14428 | O20: =N20 -> 241.14428 | P20: =O20 -> 241.14428 | ... R20: =Q20 -> 241.14428
B21: Accounts Payable | C21: Days | D21: =-D116/D28*365 -> 149.61946 | E21: =E116/E27 -> 0.22001781 | F21: =F116/F27 -> 0.18873072 | G21: =G116/G27 -> 0.18375915 | H21: =H116/H27 -> 0.14112641 | I21: =H21 -> 0.14112641 | J21: =I21 -> 0.14112641 | K21: =J21 -> 0.14112641 | L21: =K21 -> 0.14112641 | M21: =L21 -> 0.14112641 | N21: =M21 -> 0.14112641 | O21: =N21 -> 0.14112641 | P21: =O21 -> 0.14112641 | ... R21: =Q21 -> 0.14112641
B22: Capital Asset Turnover Ratio | C22: Times | D22: =D27/D51 -> 5.6583504 | E22: =E27/E51 -> 6.1026313 | F22: =F27/F51 -> 6.549432 | G22: =G27/G51 -> 7.2331386 | H22: =H27/H51 -> 7.382677 | I22: =H22+0.5 -> 7.882677 | J22: =I22+0.5 -> 8.382677 | K22: =J22+0.5 -> 8.882677 | L22: =K22+0.5 -> 9.382677 | M22: =L22+0.5 -> 9.882677 | N22: =M22+0.5 -> 10.382677 | O22: =N22+0.5 -> 10.882677 | P22: =O22+0.5 -> 11.382677 | ... R22: =Q22+0.5 -> 12.382677
A25: Income Statement
A26: INCOME
B27: Revenue | D27: ='Historial IS'!K4 -> 1406383 | E27: ='Historial IS'!L4 -> 1531376 | F27: ='Historial IS'!M4 -> 1764620 | G27: ='Historial IS'!N4 -> 2016939 | H27: ='Historial IS'!O4 -> 2365801 | I27: =H27*(I11+1) -> 2791645.2 | J27: =I27*(J11+1) -> 3266224.9 | K27: =J27*(K11+1) -> 3821483.1 | L27: =K27*(L11+1) -> 4432920.4 | M27: =L27*(M11+1) -> 5097858.4 | N27: =M27*(N11+1) -> 5837047.9 | O27: =N27*(O11+1) -> 6654234.6 | P27: =O27*(P11+1) -> 7552556.3 | ... R27: =Q27*(R11+1) -> 9601187.2
B28: Cost of Good Sold (COGS) | D28: ='Historial IS'!K9+'Historial IS'!K10+'Historial IS'!K11 -> -804774 | E28: ='Historial IS'!L9+'Historial IS'!L10+'Historial IS'!L11 -> -942680 | F28: ='Historial IS'!M9+'Historial IS'!M10+'Historial IS'!M11 -> -1060374 | G28: ='Historial IS'!N9+'Historial IS'!N10+'Historial IS'!N11 -> -1168705 | H28: ='Historial IS'!O9+'Historial IS'!O10+'Historial IS'!O11 -> -1380264 | I28: =H28*I12 -> -811492.3 | J28: =I28*J12 -> -477096.96 | K28: =J28*K12 -> -280497.43 | L28: =K28*L12 -> -164911.57 | M28: =L28*M12 -> -96955.706 | N28: =M28*N12 -> -57002.725 | O28: =N28*O12 -> -33513.351 | P28: =O28*P12 -> -19703.351 | ... R28: =Q28*R12 -> -6810.5876
B29: Gross Profit | D29: =SUM(D27:D28) -> 601609 | E29: =SUM(E27:E28) -> 588696 | F29: =SUM(F27:F28) -> 704246 | G29: =SUM(G27:G28) -> 848234 | H29: =SUM(H27:H28) -> 985537 | I29: =SUM(I27:I28) -> 1980152.9 | J29: =SUM(J27:J28) -> 2789127.9 | K29: =SUM(K27:K28) -> 3540985.7 | ... R29: =SUM(R27:R28) -> 9594376.6
A30: EXPENSES
B31: Salaries and benefits | C31: ₹ MM | D31: ='Historial IS'!K12 -> -194068 | E31: ='Historial IS'!L12 -> -210939 | F31: ='Historial IS'!M12 -> -229773 | G31: ='Historial IS'!N12 -> -246670 | H31: ='Historial IS'!O12 -> -273436 | I31: =I27*I13 -> 322654.48 | J31: =J27*J13 -> 377505.74 | K31: =K27*K13 -> 441681.72 | L31: =L27*L13 -> 512350.79 | M31: =M27*M13 -> 589203.41 | N31: =N27*N13 -> 674637.91 | O31: =O27*O13 -> 769087.21 | P31: =P27*P13 -> 872913.99 | ... R31: =R27*R13 -> 1109691.9
B32: Other operating Expenses | C32: ₹ MM | D32: ='Historial IS'!K15 -> -111421 | E32: ='Historial IS'!L15 -> -99263 | F32: ='Historial IS'!M15 -> -149211 | G32: ='Historial IS'!N15 -> -213861 | H32: ='Historial IS'!O15 -> -197508 | I32: =H32*I14 -> 0.61633999 | J32: =I32*J14 -> -1.9233398e-06 | K32: =J32*K14 -> 6.0019402e-12 | L32: =K32*L14 -> -1.8729549e-17 | M32: =L32*M14 -> 5.8447102e-23 | N32: =M32*N14 -> -1.82389e-28 | O32: =N32*O14 -> 5.6915991e-34 | P32: =O32*P14 -> -1.7761104e-39 | ... R32: =Q32*R14 -> -1.7295825e-50
B33: EBITDA | C33: ₹ MM | D33: =SUM(D29,D31:D32) -> 296120 | E33: =SUM(E29,E31:E32) -> 278494 | F33: =SUM(F29,F31:F32) -> 325262 | G33: =SUM(G29,G31:G32) -> 387703 | H33: =SUM(H29,H31:H32) -> 514593 | I33: =SUM(I29,I31:I32) -> 2302808 | J33: =SUM(J29,J31:J32) -> 3166633.6 | K33: =SUM(K29,K31:K32) -> 3982667.4 | ... R33: =SUM(R29,R31:R32) -> 10704069
B34: Depreciation & Amortization Expenses | C34: ₹ MM | D34: ='Historial IS'!K14 -> -36633 | E34: ='Historial IS'!L14 -> -38018 | F34: ='Historial IS'!M14 -> -40787 | G34: ='Historial IS'!N14 -> -41243 | H34: ='Historial IS'!O14 -> -43558 | I34: =H34*I15 -> -1237.5491 | J34: =I34*J15 -> -35.160656 | K34: =J34*K15 -> -1.3505743 | L34: =K34*L15 -> -0.051877618 | M34: =L34*M15 -> -0.0025114745 | N34: =M34*N15 -> -0.00012158431 | O34: =N34*O15 -> -7.1019245e-06 | P34: =O34*P15 -> -4.1483423e-07 | ... R34: =Q34*R15 -> -1.9414808e-09
B35: EBIT | C35: ₹ MM | D35: =SUM(D33:D34) -> 259487 | E35: =SUM(E33:E34) -> 240476 | F35: =SUM(F33:F34) -> 284475 | G35: =SUM(G33:G34) -> 346460 | H35: =SUM(H33:H34) -> 471035 | I35: =SUM(I33:I34) -> 2301570.4 | J35: =SUM(J33:J34) -> 3166598.5 | K35: =SUM(K33:K34) -> 3982666 | ... R35: =SUM(R33:R34) -> 10704069
B36: Interest | C36: ₹ MM | D36: ='Historial IS'!K13 -> -608 | E36: ='Historial IS'!L13 -> -485 | F36: ='Historial IS'!M13 -> -1479 | G36: ='Historial IS'!N13 -> -702 | H36: ='Historial IS'!O13 -> -961 | I36: =H36*I16 -> -0.39036293 | J36: =I36*J16 -> -0.00015856734 | K36: =J36*K16 -> -6.4410833e-08 | L36: =K36*L16 -> -2.6163997e-11 | M36: =L36*M16 -> -1.0627944e-14 | N36: =M36*N16 -> -4.3171232e-18 | O36: =N36*O16 -> -1.7536367e-21 | P36: =O36*P16 -> -7.1233585e-25 | ... R36: =Q36*R16 -> -1.1753715e-31
B37: Other Income (Expenses) | C37: ₹ MM | D37: ='Historial IS'!K5 -> 12610 | E37: ='Historial IS'!L5 -> 23359 | F37: ='Historial IS'!M5 -> 36002 | G37: ='Historial IS'!N5 -> 75584 | H37: ='Historial IS'!O5 -> 76759 | I37: =H37*I17 -> 2490.4648 | J37: =I37*J17 -> 80.803747 | K37: =J37*K17 -> 2.6216976 | L37: =K37*L17 -> 0.085061629 | M37: =L37*M17 -> 0.0027598457 | N37: =M37*N17 -> 8.9543876e-05 | O37: =N37*O17 -> 2.9052733e-06 | P37: =O37*P17 -> 9.4262312e-08 | ... R37: =Q37*R17 -> 9.922938e-11
B38: Earnings before Tax | C38: ₹ MM | D38: =SUM(D35:D37) -> 271489 | E38: =SUM(E35:E37) -> 263350 | F38: =SUM(F35:F37) -> 318998 | G38: =SUM(G35:G37) -> 421342 | H38: =SUM(H35:H37) -> 546833 | I38: =SUM(I35:I37) -> 2304060.5 | J38: =SUM(J35:J37) -> 3166679.3 | K38: =SUM(K35:K37) -> 3982668.6 | ... R38: =SUM(R35:R37) -> 10704069
B39: Taxes | C39: ₹ MM | D39: ='Historial IS'!K26 -> -78047 | E39: ='Historial IS'!L26 -> -101217 | F39: ='Historial IS'!M26 -> -77071 | G39: ='Historial IS'!N26 -> -158462 | H39: ='Historial IS'!O26 -> -172096 | I39: =H39*I18 -> 0 | J39: =I39*J18 -> 0 | K39: =J39*K18 -> 0 | L39: =K39*L18 -> 0 | M39: =L39*M18 -> 0 | N39: =M39*N18 -> 0 | O39: =N39*O18 -> 0 | P39: =O39*P18 -> 0 | ... R39: =Q39*R18 -> 0
B40: Net income without jv | C40: ₹ MM | D40: =D38+D39 -> 193442 | E40: =E38+E39 -> 162133 | F40: =F38+F39 -> 241927 | G40: =G38+G39 -> 262880 | H40: =H38+H39 -> 374737 | I40: =I38+I39 -> 2304060.5 | J40: =J38+J39 -> 3166679.3 | K40: =K38+K39 -> 3982668.6 | ... R40: =R38+R39 -> 10704069
B41: Net profit from jv | C41: ₹ MM | D41: 0 | E41: 0 | F41: 0 | G41: 0 | H41: 0 | I41: 0 | J41: 0 | K41: 0 | L41: 0 | M41: 0 | N41: 0 | O41: 0 | P41: 0 | Q41: 0 | R41: 0
B42: Net income from continuing operations | C42: ₹ MM | D42: =SUM(D40:D41) -> 193442 | E42: =SUM(E40:E41) -> 162133 | F42: =SUM(F40:F41) -> 241927 | G42: =SUM(G40:G41) -> 262880 | H42: =SUM(H40:H41) -> 374737 | I42: =SUM(I40:I41) -> 2304060.5 | J42: =SUM(J40:J41) -> 3166679.3 | K42: =SUM(K40:K41) -> 3982668.6 | ... R42: =SUM(R40:R41) -> 10704069
B43: Net income from discontinuing operations | C43: ₹ MM | D43: 0 | E43: 0 | F43: 0 | G43: 0 | H43: 0 | I43: 0 | J43: 0 | K43: 0 | L43: 0 | M43: 0 | N43: 0 | O43: 0 | P43: 0 | Q43: 0 | R43: 0
B44: Total net earnings | D44: =SUM(D42:D43) -> 193442 | E44: =SUM(E42:E43) -> 162133 | F44: =SUM(F42:F43) -> 241927 | G44: =SUM(G42:G43) -> 262880 | H44: =SUM(H42:H43) -> 374737 | I44: =I42+I43 -> 2304060.5 | J44: =J42+J43 -> 3166679.3 | K44: =K42+K43 -> 3982668.6 | L44: =L42+L43 -> 4780359.6 | M44: =M42+M43 -> 5590106.1 | N44: =N42+N43 -> 6454683.1 | O44: =O42+O43 -> 7389808.5 | P44: =P42+P43 -> 8405766.9 | ... R44: =R42+R43 -> 10704069
B45: dividend | C45: ₹ MM | D45: 0 | E45: 0 | F45: 0 | G45: 0 | H45: 0 | I45: 0 | J45: 0 | K45: 0 | L45: 0 | M45: 0 | N45: 0 | O45: 0 | P45: 0 | Q45: 0 | R45: 0
B46: Retained earnings | C46: ₹ MM | D46: 0 | E46: 0 | F46: 0 | G46: 0 | H46: 0 | I46: 0 | J46: 0 | K46: 0 | L46: 0 | M46: 0 | N46: 0 | O46: 0 | P46: 0 | Q46: 0 | R46: 0
A48: Balance Sheet
...

Sheet Ratio analysis
B1: Bharat Electronics Ltd
B3: Ratio analysis | C3: ='Forecasts & support schedules'!D5 -> 44286 | D3: ='Forecasts & support schedules'!E5 -> 44651 | E3: ='Forecasts & support schedules'!F5 -> 45016 | F3: ='Forecasts & support schedules'!G5 -> 45382 | G3: ='Forecasts & support schedules'!H5 -> 45747
C4: Historical | D4: Historical | E4: Historical | F4: Historical | G4: Historical
B5: Operational Ratios
B6: Quick Ratio | C6: =('Forecasts & support schedules'!D81-'Forecasts & support schedules'!D70)/'Forecasts & support schedules'!D124 -> 0.6356575 | D6: =('Forecasts & support schedules'!E81-'Forecasts & support schedules'!E70)/'Forecasts & support schedules'!E124 -> 0.63997165 | E6: =('Forecasts & support schedules'!F81-'Forecasts & support schedules'!F70)/'Forecasts & support schedules'!F124 -> 0.66494568 | F6: =('Forecasts & support schedules'!G81-'Forecasts & support schedules'!G70)/'Forecasts & support schedules'!G124 -> 0.67337024 | G6: =('Forecasts & support schedules'!H81-'Forecasts & support schedules'!H70)/'Forecasts & support schedules'!H124 -> 0.63036315
B7: Current Ratio | C7: ='Forecasts & support schedules'!D81/'Forecasts & support schedules'!D124 -> 0.8041226 | D7: ='Forecasts & support schedules'!E81/'Forecasts & support schedules'!E124 -> 0.80487299 | E7: ='Forecasts & support schedules'!F81/'Forecasts & support schedules'!F124 -> 0.84662579 | F7: ='Forecasts & support schedules'!G81/'Forecasts & support schedules'!G124 -> 0.86177185 | G7: ='Forecasts & support schedules'!H81/'Forecasts & support schedules'!H124 -> 0.85369317
B8: Interest Coverage Ratio | C8: =-'Forecasts & support schedules'!D35/'Forecasts & support schedules'!D36 -> 426.78783 | D8: =-'Forecasts & support schedules'!E35/'Forecasts & support schedules'!E36 -> 495.8268 | E8: =-'Forecasts & support schedules'!F35/'Forecasts & support schedules'!F36 -> 192.3428 | F8: =-'Forecasts & support schedules'!G35/'Forecasts & support schedules'!G36 -> 493.53276 | G8: =-'Forecasts & support schedules'!H35/'Forecasts & support schedules'!H36 -> 490.15088
B9: Fixed Asset Turnover | C9: ='Forecasts & support schedules'!D27/'Forecasts & support schedules'!D51 -> 5.6583504 | D9: ='Forecasts & support schedules'!E27/'Forecasts & support schedules'!E51 -> 6.1026313 | E9: ='Forecasts & support schedules'!F27/'Forecasts & support schedules'!F51 -> 6.549432 | F9: ='Forecasts & support schedules'!G27/'Forecasts & support schedules'!G51 -> 7.2331386 | G9: ='Forecasts & support schedules'!H27/'Forecasts & support schedules'!H51 -> 7.382677
B10: Cash Conversion Cycle | C10: ='Forecasts & support schedules'!D20-'Forecasts & support schedules'!D21 -> 75.700035 | D10: ='Forecasts & support schedules'!E20-'Forecasts & support schedules'!E21 -> 216.29497 | E10: ='Forecasts & support schedules'!F20-'Forecasts & support schedules'!F21 -> 221.76452 | F10: ='Forecasts & support schedules'!G20-'Forecasts & support schedules'!G21 -> 232.39117 | G10: ='Forecasts & support schedules'!H20-'Forecasts & support schedules'!H21 -> 241.00315
B11: Debt to Equity Ratio | C11: ='Forecasts & support schedules'!D97/'Forecasts & support schedules'!D91 -> 0 | D11: ='Forecasts & support schedules'!E97/'Forecasts & support schedules'!E91 -> 0 | E11: ='Forecasts & support schedules'!F97/'Forecasts & support schedules'!F91 -> 0 | F11: ='Forecasts & support schedules'!G97/'Forecasts & support schedules'!G91 -> 0 | G11: ='Forecasts & support schedules'!H97/'Forecasts & support schedules'!H91 -> 0
B14: Profitability Ratios
B15: Gross Margin (%) | C15: ='Forecasts & support schedules'!D29/'Forecasts & support schedules'!D27 -> 0.42777039 | D15: ='Forecasts & support schedules'!E29/'Forecasts & support schedules'!E27 -> 0.3844229 | E15: ='Forecasts & support schedules'!F29/'Forecasts & support schedules'!F27 -> 0.39909216 | F15: ='Forecasts & support schedules'!G29/'Forecasts & support schedules'!G27 -> 0.42055511 | G15: ='Forecasts & support schedules'!H29/'Forecasts & support schedules'!H27 -> 0.41657646
B16: Op Profit Margin (%) | C16: ='Forecasts & support schedules'!D35/'Forecasts & support schedules'!D27 -> 0.18450664 | D16: ='Forecasts & support schedules'!E35/'Forecasts & support schedules'!E27 -> 0.15703263 | E16: ='Forecasts & support schedules'!F35/'Forecasts & support schedules'!F27 -> 0.16121035 | F16: ='Forecasts & support schedules'!G35/'Forecasts & support schedules'!G27 -> 0.17177515 | G16: ='Forecasts & support schedules'!H35/'Forecasts & support schedules'!H27 -> 0.1991017
B17: Net Profit Margin (%) | C17: ='Forecasts & support schedules'!D44/'Forecasts & support schedules'!D27 -> 0.13754575 | D17: ='Forecasts & support schedules'!E44/'Forecasts & support schedules'!E27 -> 0.10587406 | E17: ='Forecasts & support schedules'!F44/'Forecasts & support schedules'!F27 -> 0.13709864 | F17: ='Forecasts & support schedules'!G44/'Forecasts & support schedules'!G27 -> 0.13033612 | G17: ='Forecasts & support schedules'!H44/'Forecasts & support schedules'!H27 -> 0.15839752
B18: ROCE (%) | C18: ='Forecasts & support schedules'!D35/('Forecasts & support schedules'!D84-'Forecasts & support schedules'!D107) -> 0.092992361 | D18: ='Forecasts & support schedules'!E35/('Forecasts & support schedules'!E84-'Forecasts & support schedules'!E107) -> 0.075423788 | E18: ='Forecasts & support schedules'!F35/('Forecasts & support schedules'!F84-'Forecasts & support schedules'!F107) -> 0.082585856 | F18: ='Forecasts & support schedules'!G35/('Forecasts & support schedules'!G84-'Forecasts & support schedules'!G107) -> 0.090289957 | G18: ='Forecasts & support schedules'!H35/('Forecasts & support schedules'!H84-'Forecasts & support schedules'!H107) -> 0.11851318
B21: Dupont Analysis
B23: Return on Assets (%) | C23: =C24*C25 -> 0.061022472 | D23: =D24*D25 -> 0.046722483 | E23: =E24*E25 -> 0.064497121 | F23: =F24*F25 -> 0.065426113 | G23: =G24*G25 -> 0.091775638
B24: Net Profit Margin (%) | C24: =C17 -> 0.13754575 | D24: =D17 -> 0.10587406 | E24: =E17 -> 0.13709864 | F24: =F17 -> 0.13033612 | G24: =G17 -> 0.15839752
B25: Asset Turnover ratio | C25: ='Forecasts & support schedules'!D27/AVERAGE('Forecasts & support schedules'!D84:E84) -> 0.44365219 | D25: ='Forecasts & support schedules'!E27/AVERAGE('Forecasts & support schedules'!E84:F84) -> 0.44130245 | E25: ='Forecasts & support schedules'!F27/AVERAGE('Forecasts & support schedules'!F84:G84) -> 0.47044319 | F25: ='Forecasts & support schedules'!G27/AVERAGE('Forecasts & support schedules'!G84:H84) -> 0.50197991 | G25: ='Forecasts & support schedules'!H27/AVERAGE('Forecasts & support schedules'!H84:I84) -> 0.57940074
B27: ROE (%) | C27: =C28*C29*C30 -> 0.13084085 | D27: =D28*D29*D30 -> 0.10379596 | E27: =E28*E29*E30 -> 0.13980987 | F27: =F28*F29*F30 -> 0.13650277 | G27: =G28*G29*G30 -> 0.1601643
B28: Net Profit Margin (%) | C28: =C24 -> 0.13754575 | D28: =D24 -> 0.10587406 | E28: =E24 -> 0.13709864 | F28: =F24 -> 0.13033612 | G28: =G24 -> 0.15839752
B29: Asset Turnover ratio | C29: =C25 -> 0.44365219 | D29: =D25 -> 0.44130245 | E29: =E25 -> 0.47044319 | F29: =F25 -> 0.50197991 | G29: =G25 -> 0.57940074
B30: Equity Multiplier | C30: ='Forecasts & support schedules'!D81/'Forecasts & support schedules'!D90 -> 2.144142 | D30: ='Forecasts & support schedules'!E81/'Forecasts & support schedules'!E90 -> 2.221542 | E30: ='Forecasts & support schedules'!F81/'Forecasts & support schedules'!F90 -> 2.1676917 | F30: ='Forecasts & support schedules'!G81/'Forecasts & support schedules'!G90 -> 2.0863653 | G30: ='Forecasts & support schedules'!H81/'Forecasts & support schedules'!H90 -> 1.7451723
B32: Valuation Ratios
B33: P/E | C33: 14.52x | D33: 21.42x | E33: 23.89x | F33: 36.96x | G33: 41.37x
B35: Price to Book | C35: 2.75x | D35: 4.18x | E35: 5.14x | F35: 9.01x | G35: 11.01x
B37: EV/EBITDA | C37: 9.27x | D37: 15.46x | E37: 17.45x | F37: 27.20x | G37: 31.13x

Sheet Common Size
B1: Bharat Electronics Ltd
A5: INCOME STATEMENT | D5: ='Ratio analysis'!C3 -> 44286 | E5: ='Ratio analysis'!D3 -> 44651 | F5: ='Ratio analysis'!E3 -> 45016 | G5: ='Ratio analysis'!F3 -> 45382 | H5: ='Ratio analysis'!G3 -> 45747
D6: Historical | E6: Historical | F6: Historical | G6: Historical | H6: Historical
A7: INCOME
B8: Revenue | D8: ='Forecasts & support schedules'!D27/'Forecasts & support schedules'!$D$27 -> 1 | E8: ='Forecasts & support schedules'!E27/'Forecasts & support schedules'!E27 -> 1 | F8: ='Forecasts & support schedules'!F27/'Forecasts & support schedules'!F27 -> 1 | G8: ='Forecasts & support schedules'!G27/'Forecasts & support schedules'!G27 -> 1 | H8: ='Forecasts & support schedules'!H27/'Forecasts & support schedules'!H27 -> 1
B9: Cost of Good Sold (COGS) | D9: ='Forecasts & support schedules'!D28/'Forecasts & support schedules'!$D$27 -> -0.57222961 | E9: ='Forecasts & support schedules'!E28/'Forecasts & support schedules'!E27 -> -0.6155771 | F9: ='Forecasts & support schedules'!F28/'Forecasts & support schedules'!F27 -> -0.60090784 | G9: ='Forecasts & support schedules'!G28/'Forecasts & support schedules'!G27 -> -0.57944489 | H9: ='Forecasts & support schedules'!H28/'Forecasts & support schedules'!H27 -> -0.58342354
B10: Gross Profit | D10: =D8+D9 -> 0.42777039 | E10: =E8+E9 -> 0.3844229 | F10: =F8+F9 -> 0.39909216 | G10: =G8+G9 -> 0.42055511 | H10: =H8+H9 -> 0.41657646
A11: EXPENSES
B12: Salaries and benefits | D12: ='Forecasts & support schedules'!D31/'Forecasts & support schedules'!D$28 -> 0.24114596 | E12: ='Forecasts & support schedules'!E31/'Forecasts & support schedules'!E$28 -> 0.22376522 | F12: ='Forecasts & support schedules'!F31/'Forecasts & support schedules'!F$28 -> 0.21669053 | G12: ='Forecasts & support schedules'!G31/'Forecasts & support schedules'!G$28 -> 0.21106267 | H12: ='Forecasts & support schedules'!H31/'Forecasts & support schedules'!H$28 -> 0.19810413
B13: Other operating Expenses | D13: ='Forecasts & support schedules'!D32/'Forecasts & support schedules'!D$28 -> 0.13845005 | E13: ='Forecasts & support schedules'!E32/'Forecasts & support schedules'!E$28 -> 0.10529872 | F13: ='Forecasts & support schedules'!F32/'Forecasts & support schedules'!F$28 -> 0.14071545 | G13: ='Forecasts & support schedules'!G32/'Forecasts & support schedules'!G$28 -> 0.18298972 | H13: ='Forecasts & support schedules'!H32/'Forecasts & support schedules'!H$28 -> 0.14309436
B14: EBITDA | D14: =D12+D13 -> 0.37959601 | E14: =E12+E13 -> 0.32906395 | F14: =F12+F13 -> 0.35740597 | G14: =G12+G13 -> 0.39405239 | H14: =H12+H13 -> 0.3411985
B15: Depreciation & Amortization Expenses | D15: ='Forecasts & support schedules'!D34/'Forecasts & support schedules'!D$27 -> -0.02604767 | E15: ='Forecasts & support schedules'!E34/'Forecasts & support schedules'!E$27 -> -0.024826039 | F15: ='Forecasts & support schedules'!F34/'Forecasts & support schedules'!F$27 -> -0.023113758 | G15: ='Forecasts & support schedules'!G34/'Forecasts & support schedules'!G$27 -> -0.020448313 | H15: ='Forecasts & support schedules'!H34/'Forecasts & support schedules'!H$27 -> -0.018411523
B16: EBIT | D16: =D14+D15 -> 0.35354834 | E16: =E14+E15 -> 0.30423791 | F16: =F14+F15 -> 0.33429221 | G16: =G14+G15 -> 0.37360408 | H16: =H14+H15 -> 0.32278697
B17: Interest | D17: ='Forecasts & support schedules'!D35/'Forecasts & support schedules'!D$27 -> 0.18450664 | E17: ='Forecasts & support schedules'!E35/'Forecasts & support schedules'!E$27 -> 0.15703263 | F17: ='Forecasts & support schedules'!F35/'Forecasts & support schedules'!F$27 -> 0.16121035 | G17: ='Forecasts & support schedules'!G35/'Forecasts & support schedules'!G$27 -> 0.17177515 | H17: ='Forecasts & support schedules'!H35/'Forecasts & support schedules'!H$27 -> 0.1991017
B18: Other Income (Expenses) | D18: ='Forecasts & support schedules'!D37/'Forecasts & support schedules'!D$27 -> 0.0089662631 | E18: ='Forecasts & support schedules'!E37/'Forecasts & support schedules'!E$27 -> 0.015253602 | F18: ='Forecasts & support schedules'!F37/'Forecasts & support schedules'!F$27 -> 0.020402126 | G18: ='Forecasts & support schedules'!G37/'Forecasts & support schedules'!G$27 -> 0.037474609 | H18: ='Forecasts & support schedules'!H37/'Forecasts & support schedules'!H$27 -> 0.032445248
B19: Earnings before Tax | D19: =D16-D17-D18 -> 0.16007544 | E19: =E16-E17-E18 -> 0.13195168 | F19: =F16-F17-F18 -> 0.15267974 | G19: =G16-G17-G18 -> 0.16435432 | H19: =H16-H17-H18 -> 0.091240025
B20: Taxes | D20: ='Forecasts & support schedules'!D39/'Forecasts & support schedules'!D$27 -> -0.05549484 | E20: ='Forecasts & support schedules'!E39/'Forecasts & support schedules'!E$27 -> -0.066095459 | F20: ='Forecasts & support schedules'!F39/'Forecasts & support schedules'!F$27 -> -0.043675692 | G20: ='Forecasts & support schedules'!G39/'Forecasts & support schedules'!G$27 -> -0.078565589 | H20: ='Forecasts & support schedules'!H39/'Forecasts & support schedules'!H$27 -> -0.072743227
B21: Net income without jv | D21: =D19+D20 -> 0.1045806 | E21: =E19+E20 -> 0.065856216 | F21: =F19+F20 -> 0.10900405 | G21: =G19+G20 -> 0.08578873 | H21: =H19+H20 -> 0.018496797
B22: Net profit from jv
B23: Net income from continuing operations | D23: ='Forecasts & support schedules'!D42/'Forecasts & support schedules'!D$27 -> 0.13754575 | E23: ='Forecasts & support schedules'!E42/'Forecasts & support schedules'!E$27 -> 0.10587406 | F23: ='Forecasts & support schedules'!F42/'Forecasts & support schedules'!F$27 -> 0.13709864 | G23: ='Forecasts & support schedules'!G42/'Forecasts & support schedules'!G$27 -> 0.13033612 | H23: ='Forecasts & support schedules'!H42/'Forecasts & support schedules'!H$27 -> 0.15839752
B24: Net income from discontinuing operations
B25: Total net earnings | D25: =D23 -> 0.13754575 | E25: =E23 -> 0.10587406 | F25: =F23 -> 0.13709864 | G25: =G23 -> 0.13033612 | H25: =H23 -> 0.15839752
B27: Balance sheet | D27: 2020 | E27: =D27+1 -> 2021 | F27: =E27+1 -> 2022 | G27: =F27+1 -> 2023 | H27: =G27+1 -> 2024
D28: Historical | E28: Historical | F28: Historical | G28: Historical | H28: Historical
B30: ='Forecasts & support schedules'!B50 -> Non - current assets
B31: ='Forecasts & support schedules'!B51 -> ( a ) Property , Plant and Equipment | D31: ='Forecasts & support schedules'!D51/'Forecasts & support schedules'!D$67 -> 0.43028828 | E31: ='Forecasts & support schedules'!E51/'Forecasts & support schedules'!E$67 -> 0.37923822 | F31: ='Forecasts & support schedules'!F51/'Forecasts & support schedules'!F$67 -> 0.49496549 | G31: ='Forecasts & support schedules'!G51/'Forecasts & support schedules'!G$67 -> 0.51036294 | H31: ='Forecasts & support schedules'!H51/'Forecasts & support schedules'!H$67 -> 0.53641458
B32: ='Forecasts & support schedules'!B52 -> ( b ) Capital work - in - progress | D32: ='Forecasts & support schedules'!D52/'Forecasts & support schedules'!D$67 -> 0.068809769 | E32: ='Forecasts & support schedules'!E52/'Forecasts & support schedules'!E$67 -> 0.067392891 | F32: ='Forecasts & support schedules'!F52/'Forecasts & support schedules'!F$67 -> 0.066360732 | G32: ='Forecasts & support schedules'!G52/'Forecasts & support schedules'!G$67 -> 0.083536797 | H32: ='Forecasts & support schedules'!H52/'Forecasts & support schedules'!H$67 -> 0.079842919
B33: ='Forecasts & support schedules'!B53 -> ( c ) Investment Property | D33: ='Forecasts & support schedules'!D53/'Forecasts & support schedules'!D$67 -> 1.3849552e-05 | E33: ='Forecasts & support schedules'!E53/'Forecasts & support schedules'!E$67 -> 1.057902e-05 | F33: ='Forecasts & support schedules'!F53/'Forecasts & support schedules'!F$67 -> 1.1022462e-05 | G33: ='Forecasts & support schedules'!G53/'Forecasts & support schedules'!G$67 -> 7.3210462e-06 | H33: ='Forecasts & support schedules'!H53/'Forecasts & support schedules'!H$67 -> 6.6957037e-06
B34: ='Forecasts & support schedules'!B54 -> ( d ) Goodwill | D34: ='Forecasts & support schedules'!D54/'Forecasts & support schedules'!D$67 -> 0 | E34: ='Forecasts & support schedules'!E54/'Forecasts & support schedules'!E$67 -> 0 | F34: ='Forecasts & support schedules'!F54/'Forecasts & support schedules'!F$67 -> 0 | G34: ='Forecasts & support schedules'!G54/'Forecasts & support schedules'!G$67 -> 0 | H34: ='Forecasts & support schedules'!H54/'Forecasts & support schedules'!H$67 -> 0
B35: ='Forecasts & support schedules'!B55 -> ( e ) Other Intangible assets | D35: ='Forecasts & support schedules'!D55/'Forecasts & support schedules'!D$67 -> 0.028834768 | E35: ='Forecasts & support schedules'!E55/'Forecasts & support schedules'!E$67 -> 0.025060187 | F35: ='Forecasts & support schedules'!F55/'Forecasts & support schedules'!F$67 -> 0.04932368 | G35: ='Forecasts & support schedules'!G55/'Forecasts & support schedules'!G$67 -> 0.045152552 | H35: ='Forecasts & support schedules'!H55/'Forecasts & support schedules'!H$67 -> 0.035932494
B36: ='Forecasts & support schedules'!B56 -> ( f ) Intangible Assets under Development | D36: ='Forecasts & support schedules'!D56/'Forecasts & support schedules'!D$67 -> 0.083999266 | E36: ='Forecasts & support schedules'!E56/'Forecasts & support schedules'!E$67 -> 0.084648784 | F36: ='Forecasts & support schedules'!F56/'Forecasts & support schedules'!F$67 -> 0.090698328 | G36: ='Forecasts & support schedules'!G56/'Forecasts & support schedules'!G$67 -> 0.080037337 | H36: ='Forecasts & support schedules'!H56/'Forecasts & support schedules'!H$67 -> 0.09622061
B37: ='Forecasts & support schedules'!B57 -> ( g ) Investments accounted for using the Equity Method | D37: ='Forecasts & support schedules'!D57/'Forecasts & support schedules'!D$67 -> 0.032873644 | E37: ='Forecasts & support schedules'!E57/'Forecasts & support schedules'!E$67 -> 0.035200933 | F37: ='Forecasts & support schedules'!F57/'Forecasts & support schedules'!F$67 -> 0.036875646 | G37: ='Forecasts & support schedules'!G57/'Forecasts & support schedules'!G$67 -> 0.027741274 | H37: ='Forecasts & support schedules'!H57/'Forecasts & support schedules'!H$67 -> 0.027010469
B38: ='Forecasts & support schedules'!B58 -> ( h ) Financial Assets | D38: ='Forecasts & support schedules'!D58/'Forecasts & support schedules'!D$67 -> 0 | E38: ='Forecasts & support schedules'!E58/'Forecasts & support schedules'!E$67 -> 0 | F38: ='Forecasts & support schedules'!F58/'Forecasts & support schedules'!F$67 -> 0 | G38: ='Forecasts & support schedules'!G58/'Forecasts & support schedules'!G$67 -> 0 | H38: ='Forecasts & support schedules'!H58/'Forecasts & support schedules'!H$67 -> 0
B39: ='Forecasts & support schedules'!B59 -> ( i ) Investments | D39: ='Forecasts & support schedules'!D59/'Forecasts & support schedules'!D$67 -> 0.19320991 | E39: ='Forecasts & support schedules'!E59/'Forecasts & support schedules'!E$67 -> 0.20237665 | F39: ='Forecasts & support schedules'!F59/'Forecasts & support schedules'!F$67 -> 0.082532521 | G39: ='Forecasts & support schedules'!G59/'Forecasts & support schedules'!G$67 -> 0.097124659 | H39: ='Forecasts & support schedules'!H59/'Forecasts & support schedules'!H$67 -> 0.097357206
B40: ='Forecasts & support schedules'!B60 -> ( ii ) Trade Receivables | D40: ='Forecasts & support schedules'!D60/'Forecasts & support schedules'!D$67 -> 0 | E40: ='Forecasts & support schedules'!E60/'Forecasts & support schedules'!E$67 -> 0 | F40: ='Forecasts & support schedules'!F60/'Forecasts & support schedules'!F$67 -> 0 | G40: ='Forecasts & support schedules'!G60/'Forecasts & support schedules'!G$67 -> 0 | H40: ='Forecasts & support schedules'!H60/'Forecasts & support schedules'!H$67 -> 0
B41: ='Forecasts & support schedules'!B61 -> ( iii ) Contract Assets | D41: ='Forecasts & support schedules'!D61/'Forecasts & support schedules'!D$67 -> 0 | E41: ='Forecasts & support schedules'!E61/'Forecasts & support schedules'!E$67 -> 0 | F41: ='Forecasts & support schedules'!F61/'Forecasts & support schedules'!F$67 -> 0 | G41: ='Forecasts & support schedules'!G61/'Forecasts & support schedules'!G$67 -> 0 | H41: ='Forecasts & support schedules'!H61/'Forecasts & support schedules'!H$67 -> 0
